<?xml version="1.0"?>
<robot name="GTC50-2" xmlns:xacro="http://ros.org/wiki/xacro">
<!-- Defining the colors used in this robot -->
    <material name="Black">
        <color rgba="0 0 0 1"/>
    </material>

    <material name="White">
        <color rgba="1 1 1 1"/>
    </material>

    <material name="Blue">
        <color rgba="0 0 1 1"/>
    </material>

    <material name="Red">
        <color rgba="1 0 0 1"/>
    </material>
	
    <!-- /////////////////////////////////////   BASE LINK    ////////////////////////////////////////////// -->
    <link name="base_link" >
        <visual>
            <origin xyz="-2.0549E-17 -1.7764E-15 0.51059" rpy="0 0 0" />
            <geometry>
               <mesh
                  filename="package://GTC50-2/meshes/base_link.STL" />
            </geometry>
            <material name="Black" />
        </visual>
        <collision>
            <origin xyz="0 0 0" rpy="0 0 0" />
            <geometry>
                <mesh
                  filename="package://GTC50-2/meshes/base_link.STL" />
            </geometry>
        </collision>
        <xacro:macro name="inertial_matrix" params="mass">
          <inertial>
             <mass value="7953.2" />
             <inertia 
				ixx="1348"
				ixy="7.4526E-14"
				ixz="5.3421E-14"
				iyy="1348"
				iyz="5.7289E-14"
				izz="1304.8" />
          </inertial>
        </xacro:macro>
    </link>

    <joint name="joint1" type="revolute">
        <parent link="base_link"/>
        <child link="link1"/>
        <origin xyz="0 0 1.1" rpy="0 0 0" />
        <axis xyz="0 0 1" />
        <limit effort="0" velocity="4" lower="-3.14" upper="3.14"/>
    </joint>
	
	<!-- /////////////////////////////////////   LINK1  ////////////////////////////////////////////// -->
    <link name="link1" >
        <visual>
            <origin xyz="0.002964 0.14026 0.13352" rpy="0 0 0" />
            <geometry>
               <mesh
                  filename="package://GTC50-2/meshes/link1.STL" />
            </geometry>
            <material name="White" />
        </visual>
        <collision>
            <origin xyz="0 0 0" rpy="0 0 0" />
            <geometry>
                <mesh
                  filename="package://GTC50-2/meshes/link1.STL" />
            </geometry>
        </collision>
        <xacro:macro name="inertial_matrix" params="mass">
          <inertial>
             <mass value="218.24" />
             <inertia 
				ixx="59.651"
				ixy="-3.1256E-05"
				ixz="-5.5082E-05"
				iyy="3.8964"
				iyz="3.2551"
				izz="60.618"  />
          </inertial>
        </xacro:macro>
    </link>

    <joint name="joint2" type="revolute">
        <parent link="link1"/>
        <child link="link2"/>
        <origin xyz="0 0.75 0.095" rpy="0 1.5708 0" />
        <axis xyz="0 0 1" />
        <limit effort="0" velocity="2" lower="-0.9519" upper="0" />
    </joint>
	
		<!-- /////////////////////////////////////   LINK2  ////////////////////////////////////////////// -->
    <link name="link2" >
        <visual>
            <origin xyz="-0.47876 -0.2711 -6.2903E-05" rpy="0 0 0" />
            <geometry>
               <mesh
                  filename="package://GTC50-2/meshes/link2.STL" />
            </geometry>
            <material name="Blue" />
        </visual>
        <collision>
            <origin xyz="0 0 0" rpy="0 0 0" />
            <geometry>
                <mesh
                  filename="package://GTC50-2/meshes/link2.STL" />
            </geometry>
        </collision>
        <xacro:macro name="inertial_matrix" params="mass">
          <inertial>
             <mass value="342.44" />
             <inertia 
				ixx="14.567"
				ixy="-6.5681"
				ixz="0.0019427"
				iyy="22.012"
				iyz="0.00025703"
				izz="20.128" />
          </inertial>
        </xacro:macro>
    </link>

    <joint name="joint3" type="revolute">
        <parent link="link2"/>
        <child link="link3"/>
        <origin xyz="-0.8702 -0.4927 0" rpy="0 0 0" />
        <axis xyz="0 0 1" />
        <limit effort="0" velocity="2" lower="0" upper="0.8753" />
    </joint>
	
		<!-- /////////////////////////////////////   LINK3  ////////////////////////////////////////////// -->
    <link name="link3" >
        <visual>
            <origin xyz="-0.0017701 1.4006 0.00075554" rpy="0 0 0" />
            <geometry>
               <mesh
                  filename="package://GTC50-2/meshes/link3.STL" />
            </geometry>
            <material name="Red" />
        </visual>
        <collision>
            <origin xyz="0 0 0" rpy="0 0 0" />
            <geometry>
                <mesh
                  filename="package://GTC50-2/meshes/link3.STL" />
            </geometry>
        </collision>
        <xacro:macro name="inertial_matrix" params="mass">
          <inertial>
             <mass value="324.33" />
             <inertia 
				ixx="232.76"
				ixy="6.315"
				ixz="1.0378E-05"
				iyy="5.0359"
				iyz="-9.7654E-05"
				izz="232.62" />
          </inertial>
        </xacro:macro>
    </link>

    <joint name="joint4" type="revolute">
        <parent link="link3"/>
        <child link="link4"/>
        <origin xyz="-0.053202 2.6495 0" rpy="0 0 0" />
        <axis xyz="0 0 -1" />
        <limit effort="0" velocity="3" lower="0" upper="1.575" />
    </joint>
	
		<!-- /////////////////////////////////////   LINK4  ////////////////////////////////////////////// -->
    <link name="link4" >
        <visual>
            <origin xyz="-0.038943 0.66186 -4.3235E-05" rpy="0 0 0" />
            <geometry>
               <mesh
                  filename="package://GTC50-2/meshes/link4.STL" />
            </geometry>
            <material name="Black" />
        </visual>
        <collision>
            <origin xyz="0 0 0" rpy="0 0 0" />
            <geometry>
                <mesh
                  filename="package://GTC50-2/meshes/link4.STL" />
            </geometry>
        </collision>
        <xacro:macro name="inertial_matrix" params="mass">
          <inertial>
             <mass value="172.24" />
             <inertia 
				ixx="43.859"
				ixy="-0.88737"
				ixz="6.9078E-05"
				iyy="2.6386"
				iyz="0.0019024"
				izz="45.288" />
          </inertial>
        </xacro:macro>
    </link>

    <joint name="joint5" type="revolute">
        <parent link="link4"/>
        <child link="link5"/>
        <origin xyz="-0.042868 1.3893 0" rpy="0 0 -3.1416" />
        <axis xyz="0 0 1" />
        <limit effort="0" velocity="4" lower="0" upper="1.9763" />
    </joint>
	
	<!-- /////////////////////////////////////   LINK5  ////////////////////////////////////////////// -->
    <link name="link5" >
        <visual>
            <origin xyz="-0.11365 -0.18369 -1.4957E-06" rpy="0 0 0" />
            <geometry>
               <mesh
                  filename="package://GTC50-2/meshes/link5.STL" />
            </geometry>
            <material name="White" />
        </visual>
        <collision>
            <origin xyz="0 0 0" rpy="0 0 0" />
            <geometry>
                <mesh
                  filename="package://GTC50-2/meshes/link5.STL" />
            </geometry>
        </collision>
        <xacro:macro name="inertial_matrix" params="mass">
          <inertial>
             <mass value="53.032" />
             <inertia 
				ixx="2.7776"
				ixy="-0.077008"
				ixz="1.0708E-05"
				iyy="1.26"
				iyz="1.0637E-06"
				izz="1.8376" />
          </inertial>
        </xacro:macro>
    </link>

    <joint name="joint6" type="revolute">
        <parent link="link5"/>
        <child link="link6"/>
        <origin xyz="-0.20616 -0.20358 0" rpy="1.6125 1.5708 0" />
        <axis xyz="0 0 1" />
        <limit effort="0" velocity="2" lower="-0.349" upper="0.349" />
    </joint>
	
	<!-- /////////////////////////////////////   LINK6  ////////////////////////////////////////////// -->
    <link name="link6" >
        <visual>
            <origin xyz="-0.00041221973600064 -0.202307104320946 -0.0600398242569957" rpy="0 0 0" />
            <geometry>
               <mesh
                  filename="package://GTC50-2/meshes/link6.STL" />
            </geometry>
            <material name="Blue" />
        </visual>
        <collision>
            <origin xyz="0 0 0" rpy="0 0 0" />
            <geometry>
                <mesh
                  filename="package://GTC50-2/meshes/link6.STL" />
            </geometry>
        </collision>
        <xacro:macro name="inertial_matrix" params="mass">
          <inertial>
             <mass value="0.433989502848618" />
             <inertia 
				ixx="0.00610128466971713"
				ixy="1.19032662470519E-05"
				ixz="6.44789237018948E-08"
				iyy="0.0121840053750568"
				iyz="2.16412250777067E-10"
				izz="0.00609561897305626" />
          </inertial>
        </xacro:macro>
    </link>

    <joint name="joint7" type="revolute">
        <parent link="link6"/>
        <child link="link7"/>
        <origin xyz="-0.0004469 -0.22841 -0.065" rpy="1.5708 0 -0.0019566" />
        <axis xyz="0 0 -1" />
        <limit effort="0" velocity="2" lower="-3.14" upper="3.14" />
    </joint>
	
	<!-- /////////////////////////////////////   LINK7  ////////////////////////////////////////////// -->
    <link name="link7" >
        <visual>
            <origin xyz="0.0192701173261565 -0.0531322033474377 0.700688613014507" rpy="0 0 0" />
            <geometry>
               <mesh
                  filename="package://GTC50-2/meshes/link7.STL" />
            </geometry>
            <material name="White" />
        </visual>
        <collision>
            <origin xyz="0 0 0" rpy="0 0 0" />
            <geometry>
                <mesh
                  filename="package://GTC50-2/meshes/link7.STL" />
            </geometry>
        </collision>
        <xacro:macro name="inertial_matrix" params="mass">
          <inertial>
             <mass value="635.22530453949" />
             <inertia 
				ixx="32.6657532627053"
				ixy="-0.0166299811508729"
				ixz="1.19772530834127"
				iyy="23.7143855534864"
				iyz="0.316508867780156"
				izz="22.5291260378258" />
          </inertial>
        </xacro:macro>
    </link>
	
	<!-- Grasping frame -->
    <link name="grasping_frame"/>

    <joint name="grasping_frame_joint" type="fixed">
      <parent link="link6"/>
      <child link="grasping_frame"/>
      <origin xyz="0.0023704 -0.066977 0.87282" rpy="0.077368 0.0028185 0.020673"/>
	  <axis xyz="0 0 0" />
    </joint>
	
	<!-- /////////////////////////////////   Gazebo   ////////////////////////////////////// -->
 
    <gazebo reference="base_link">
        <material>Gazebo/Black</material>
    </gazebo>
    <gazebo reference="link1">
        <material>Gazebo/White</material>
    </gazebo>
    <gazebo reference="link2">
        <material>Gazebo/Blue</material>
    </gazebo>
    <gazebo reference="link3">
        <material>Gazebo/Red</material>
    </gazebo>
    <gazebo reference="link4">
        <material>Gazebo/Black</material>
    </gazebo>
    <gazebo reference="link5">
        <material>Gazebo/White</material>
    </gazebo>
    <gazebo reference="link6">
        <material>Gazebo/Blue</material>
    </gazebo>
    <gazebo reference="link7">
        <material>Gazebo/Red</material>
    </gazebo>
	
	<!-- Transmissions for ROS Control -->
    <xacro:macro name="transmission_block" params="joint_name">
        <transmission name="tran1">
            <type>transmission_interface/SimpleTransmission</type>
            <joint name="${joint_name}">
                <hardwareInterface>hardware_interface/PositionJointInterface</hardwareInterface>
            </joint>
            <actuator name="motor1">
                <hardwareInterface>hardware_interface/PositionJointInterface</hardwareInterface>
                <mechanicalReduction>1</mechanicalReduction>
            </actuator>
        </transmission>
    </xacro:macro>
    
    <xacro:transmission_block joint_name="joint1"/>
    <xacro:transmission_block joint_name="joint2"/>
    <xacro:transmission_block joint_name="joint3"/>
    <xacro:transmission_block joint_name="joint4"/>
    <xacro:transmission_block joint_name="joint5"/>
    <xacro:transmission_block joint_name="joint6"/>
    <xacro:transmission_block joint_name="joint7"/>

    <!-- ros_control plugin -->
    <gazebo>
        <plugin name="gazebo_ros_control" filename="libgazebo_ros_control.so">
            <robotNamespace>/GTC50-2</robotNamespace>
        </plugin>
    </gazebo>

</robot>
